<?xml version="1.0" ?>
<!-- =================================================================================== -->
<!-- |    This document was autogenerated by xacro from mh5lsii.xacro                  | -->
<!-- |    EDITING THIS FILE BY HAND IS NOT RECOMMENDED                                 | -->
<!-- =================================================================================== -->
<robot name="mh5lsii">
  <material name="silver">
    <color rgba="0.700 0.700 0.700 1.000"/>
  </material>
  <transmission name="rev1_tran">
    <type>transmission_interface/SimpleTransmission</type>
    <joint name="rev1">
      <hardwareInterface>hardware_interface/EffortJointInterface</hardwareInterface>
    </joint>
    <actuator name="rev1_actr">
      <hardwareInterface>hardware_interface/EffortJointInterface</hardwareInterface>
      <mechanicalReduction>1</mechanicalReduction>
    </actuator>
  </transmission>
  <transmission name="rev2_tran">
    <type>transmission_interface/SimpleTransmission</type>
    <joint name="rev2">
      <hardwareInterface>hardware_interface/EffortJointInterface</hardwareInterface>
    </joint>
    <actuator name="rev2_actr">
      <hardwareInterface>hardware_interface/EffortJointInterface</hardwareInterface>
      <mechanicalReduction>1</mechanicalReduction>
    </actuator>
  </transmission>
  <transmission name="rev3_tran">
    <type>transmission_interface/SimpleTransmission</type>
    <joint name="rev3">
      <hardwareInterface>hardware_interface/EffortJointInterface</hardwareInterface>
    </joint>
    <actuator name="rev3_actr">
      <hardwareInterface>hardware_interface/EffortJointInterface</hardwareInterface>
      <mechanicalReduction>1</mechanicalReduction>
    </actuator>
  </transmission>
  <transmission name="rev4_tran">
    <type>transmission_interface/SimpleTransmission</type>
    <joint name="rev4">
      <hardwareInterface>hardware_interface/EffortJointInterface</hardwareInterface>
    </joint>
    <actuator name="rev4_actr">
      <hardwareInterface>hardware_interface/EffortJointInterface</hardwareInterface>
      <mechanicalReduction>1</mechanicalReduction>
    </actuator>
  </transmission>
  <transmission name="rev5_tran">
    <type>transmission_interface/SimpleTransmission</type>
    <joint name="rev5">
      <hardwareInterface>hardware_interface/EffortJointInterface</hardwareInterface>
    </joint>
    <actuator name="rev5_actr">
      <hardwareInterface>hardware_interface/EffortJointInterface</hardwareInterface>
      <mechanicalReduction>1</mechanicalReduction>
    </actuator>
  </transmission>
  <transmission name="rev6_tran">
    <type>transmission_interface/SimpleTransmission</type>
    <joint name="rev6">
      <hardwareInterface>hardware_interface/EffortJointInterface</hardwareInterface>
    </joint>
    <actuator name="rev6_actr">
      <hardwareInterface>hardware_interface/EffortJointInterface</hardwareInterface>
      <mechanicalReduction>1</mechanicalReduction>
    </actuator>
  </transmission>
  <transmission name="slider9_tran">
    <type>transmission_interface/SimpleTransmission</type>
    <joint name="slider9">
      <hardwareInterface>hardware_interface/EffortJointInterface</hardwareInterface>
    </joint>
    <actuator name="slider9_actr">
      <hardwareInterface>hardware_interface/EffortJointInterface</hardwareInterface>
      <mechanicalReduction>1</mechanicalReduction>
    </actuator>
  </transmission>
  <transmission name="slider10_tran">
    <type>transmission_interface/SimpleTransmission</type>
    <joint name="slider10">
      <hardwareInterface>hardware_interface/EffortJointInterface</hardwareInterface>
    </joint>
    <actuator name="slider10_actr">
      <hardwareInterface>hardware_interface/EffortJointInterface</hardwareInterface>
      <mechanicalReduction>1</mechanicalReduction>
    </actuator>
  </transmission>
  <gazebo>
    <plugin filename="libgazebo_ros_control.so" name="control"/>
  </gazebo>
  <gazebo reference="base_link">
    <material>Gazebo/Silver</material>
    <mu1>0.2</mu1>
    <mu2>0.2</mu2>
    <selfCollide>true</selfCollide>
    <gravity>true</gravity>
  </gazebo>
  <gazebo reference="link_01_1">
    <material>Gazebo/Silver</material>
    <mu1>0.2</mu1>
    <mu2>0.2</mu2>
    <selfCollide>true</selfCollide>
  </gazebo>
  <gazebo reference="link_02_1">
    <material>Gazebo/Silver</material>
    <mu1>0.2</mu1>
    <mu2>0.2</mu2>
    <selfCollide>true</selfCollide>
  </gazebo>
  <gazebo reference="link_03_1">
    <material>Gazebo/Silver</material>
    <mu1>0.2</mu1>
    <mu2>0.2</mu2>
    <selfCollide>true</selfCollide>
  </gazebo>
  <gazebo reference="link_04_1">
    <material>Gazebo/Silver</material>
    <mu1>0.2</mu1>
    <mu2>0.2</mu2>
    <selfCollide>true</selfCollide>
  </gazebo>
  <gazebo reference="link_05_1">
    <material>Gazebo/Silver</material>
    <mu1>0.2</mu1>
    <mu2>0.2</mu2>
    <selfCollide>true</selfCollide>
  </gazebo>
  <gazebo reference="link_06_1">
    <material>Gazebo/Silver</material>
    <mu1>0.2</mu1>
    <mu2>0.2</mu2>
    <selfCollide>true</selfCollide>
  </gazebo>
  <gazebo reference="acople_1">
    <material>Gazebo/Silver</material>
    <mu1>0.2</mu1>
    <mu2>0.2</mu2>
    <selfCollide>true</selfCollide>
  </gazebo>
  <gazebo reference="ob7_2_1">
    <material>Gazebo/Silver</material>
    <mu1>0.2</mu1>
    <mu2>0.2</mu2>
    <selfCollide>true</selfCollide>
  </gazebo>
  <gazebo reference="ob7_slider_d_1">
    <material>Gazebo/Silver</material>
    <mu1>0.2</mu1>
    <mu2>0.2</mu2>
    <selfCollide>true</selfCollide>
  </gazebo>
  <gazebo reference="ob7_slider_i_1">
    <material>Gazebo/Silver</material>
    <mu1>0.2</mu1>
    <mu2>0.2</mu2>
    <selfCollide>true</selfCollide>
  </gazebo>
  <gazebo reference="ob7_finger_d_1">
    <material>Gazebo/Silver</material>
    <mu1>0.2</mu1>
    <mu2>0.2</mu2>
    <selfCollide>true</selfCollide>
  </gazebo>
  <gazebo reference="ob7_finger_i_1">
    <material>Gazebo/Silver</material>
    <mu1>0.2</mu1>
    <mu2>0.2</mu2>
    <selfCollide>true</selfCollide>
  </gazebo>
  <link name="base_link">
    <inertial>
      <origin rpy="0 0 0" xyz="-0.011090103739351596 0.00022797791882665918 0.10315518556214519"/>
      <mass value="6.766314683371327"/>
      <!-- <inertia ixx="0.039535" ixy="0.000175" ixz="-0.000486" iyy="0.044975" iyz="4.1e-05" izz="0.033128"/> -->
      <inertia ixx="0.039535" ixy="0.000175" ixz="-0.000486" iyy="0.044975" iyz="4.1e-05" izz="0.033128"/>
      
    </inertial>
    <visual>
      <origin rpy="0 0 0" xyz="0 0 0"/>
      <geometry>
        <mesh filename="package://mh5lsii_description/meshes/base_link.stl" scale="0.001 0.001 0.001"/>
      </geometry>
      <material name="silver"/>
    </visual>
    <collision>
      <origin rpy="0 0 0" xyz="0 0 0"/>
      <geometry>
        <mesh filename="package://mh5lsii_description/meshes/base_link.stl" scale="0.001 0.001 0.001"/>
      </geometry>
    </collision>
  </link>
  <link name="link_01_1">
    <inertial>
      <origin rpy="0 0 0" xyz="0.049423257467588036 -0.00240150574806688 0.06287800300541616"/>
      <mass value="2.74595411805442"/>
      <inertia ixx="0.009639" ixy="0.000288" ixz="-0.004201" iyy="0.014176" iyz="0.000294" izz="0.011386"/>
    </inertial>
    <visual>
      <origin rpy="0 0 0" xyz="0.0 -0.0 -0.229"/>
      <geometry>
        <mesh filename="package://mh5lsii_description/meshes/link_01_1.stl" scale="0.001 0.001 0.001"/>
      </geometry>
      <material name="silver"/>
    </visual>
    <collision>
      <origin rpy="0 0 0" xyz="0.0 -0.0 -0.229"/>
      <geometry>
        <mesh filename="package://mh5lsii_description/meshes/link_01_1.stl" scale="0.001 0.001 0.001"/>
      </geometry>
    </collision>
  </link>
  <link name="link_02_1">
    <inertial>
      <origin rpy="0 0 0" xyz="-0.005331923635036859 0.06418219806904472 0.17365649623351526"/>
      <mass value="6.763318661710877"/>
      <inertia ixx="0.149826" ixy="0.000123" ixz="-4.7e-05" iyy="0.116633" iyz="0.001011" izz="0.044132"/>
    </inertial>
    <visual>
      <origin rpy="0 0 0" xyz="-0.088 0.0635 -0.33"/>
      <geometry>
        <mesh filename="package://mh5lsii_description/meshes/link_02_1.stl" scale="0.001 0.001 0.001"/>
      </geometry>
      <material name="silver"/>
    </visual>
    <collision>
      <origin rpy="0 0 0" xyz="-0.088 0.0635 -0.33"/>
      <geometry>
        <mesh filename="package://mh5lsii_description/meshes/link_02_1.stl" scale="0.001 0.001 0.001"/>
      </geometry>
    </collision>
  </link>
  <link name="link_03_1">
    <inertial>
      <origin rpy="0 0 0" xyz="-0.010417850763689798 -0.06566047170765882 0.019063299663247935"/>
      <mass value="2.681871492262554"/>
      <inertia ixx="0.007254" ixy="3.3e-05" ixz="-0.000788" iyy="0.009118" iyz="-3.4e-05" izz="0.008082"/>
    </inertial>
    <visual>
      <origin rpy="0 0 0" xyz="-0.088 -0.0645 -0.73"/>
      <geometry>
        <mesh filename="package://mh5lsii_description/meshes/link_03_1.stl" scale="0.001 0.001 0.001"/>
      </geometry>
      <material name="silver"/>
    </visual>
    <collision>
      <origin rpy="0 0 0" xyz="-0.088 -0.0645 -0.73"/>
      <geometry>
        <mesh filename="package://mh5lsii_description/meshes/link_03_1.stl" scale="0.001 0.001 0.001"/>
      </geometry>
    </collision>
  </link>
  <link name="link_04_1">
    <inertial>
      <origin rpy="0 0 0" xyz="0.16098681758129338 -6.09203263927216e-06 0.00017633845563469475"/>
      <mass value="3.0345870906853607"/>
      <inertia ixx="0.005212" ixy="-1.2e-05" ixz="1e-06" iyy="0.026116" iyz="-8e-06" izz="0.027027"/>
    </inertial>
    <visual>
      <origin rpy="0 0 0" xyz="-0.1585 0.0 -0.77"/>
      <geometry>
        <mesh filename="package://mh5lsii_description/meshes/link_04_1.stl" scale="0.001 0.001 0.001"/>
      </geometry>
      <material name="silver"/>
    </visual>
    <collision>
      <origin rpy="0 0 0" xyz="-0.1585 0.0 -0.77"/>
      <geometry>
        <mesh filename="package://mh5lsii_description/meshes/link_04_1.stl" scale="0.001 0.001 0.001"/>
      </geometry>
    </collision>
  </link>
  <link name="link_05_1">
    <inertial>
      <origin rpy="0 0 0" xyz="0.015586640791618978 -0.030964064569894863 -0.00016446853214213686"/>
      <mass value="0.37951137478480873"/>
      <inertia ixx="0.00025" ixy="0.0" ixz="-1e-06" iyy="0.000452" iyz="1e-06" izz="0.000432"/>
    </inertial>
    <visual>
      <origin rpy="0 0 0" xyz="-0.493 -0.030999 -0.770249"/>
      <geometry>
        <mesh filename="package://mh5lsii_description/meshes/link_05_1.stl" scale="0.001 0.001 0.001"/>
      </geometry>
      <material name="silver"/>
    </visual>
    <collision>
      <origin rpy="0 0 0" xyz="-0.493 -0.030999 -0.770249"/>
      <geometry>
        <mesh filename="package://mh5lsii_description/meshes/link_05_1.stl" scale="0.001 0.001 0.001"/>
      </geometry>
    </collision>
  </link>
  <link name="link_06_1">
    <inertial>
      <origin rpy="0 0 0" xyz="0.01450144512471463 -4.057700439152878e-07 4.975171074528273e-05"/>
      <mass value="0.04311612297123868"/>
      <inertia ixx="1.1e-05" ixy="0.0" ixz="-0.0" iyy="8e-06" iyz="-0.0" izz="8e-06"/>
    </inertial>
    <visual>
      <origin rpy="0 0 0" xyz="-0.5435 0.0 -0.77"/>
      <geometry>
        <mesh filename="package://mh5lsii_description/meshes/link_06_1.stl" scale="0.001 0.001 0.001"/>
      </geometry>
      <material name="silver"/>
    </visual>
    <collision>
      <origin rpy="0 0 0" xyz="-0.5435 0.0 -0.77"/>
      <geometry>
        <mesh filename="package://mh5lsii_description/meshes/link_06_1.stl" scale="0.001 0.001 0.001"/>
      </geometry>
    </collision>
  </link>
  <link name="acople_1">
    <inertial>
      <origin rpy="0 0 0" xyz="0.015817002581675066 6.69007210366947e-07 -1.1276651433744789e-06"/>
      <mass value="0.055705114869669475"/>
      <inertia ixx="2.8e-05" ixy="0.0" ixz="-0.0" iyy="1.5e-05" iyz="0.0" izz="1.5e-05"/>
    </inertial>
    <visual>
      <origin rpy="0 0 0" xyz="-0.567 0.0 -0.77"/>
      <geometry>
        <mesh filename="package://mh5lsii_description/meshes/acople_1.stl" scale="0.001 0.001 0.001"/>
      </geometry>
      <material name="silver"/>
    </visual>
    <collision>
      <origin rpy="0 0 0" xyz="-0.567 0.0 -0.77"/>
      <geometry>
        <mesh filename="package://mh5lsii_description/meshes/acople_1.stl" scale="0.001 0.001 0.001"/>
      </geometry>
    </collision>
  </link>
  <link name="ob7_2_1">
    <inertial>
      <origin rpy="0 0 0" xyz="0.07017691342571097 1.194951294536395e-07 -3.4271062391288964e-06"/>
      <mass value="0.3085040405049697"/>
      <inertia ixx="0.000178" ixy="-0.0" ixz="0.0" iyy="0.00053" iyz="-0.0" izz="0.000577"/>
    </inertial>
    <visual>
      <origin rpy="0 0 0" xyz="-0.590997 0.0 -0.77"/>
      <geometry>
        <mesh filename="package://mh5lsii_description/meshes/ob7_2_1.stl" scale="0.001 0.001 0.001"/>
      </geometry>
      <material name="silver"/>
    </visual>
    <collision>
      <origin rpy="0 0 0" xyz="-0.590997 0.0 -0.77"/>
      <geometry>
        <mesh filename="package://mh5lsii_description/meshes/ob7_2_1.stl" scale="0.001 0.001 0.001"/>
      </geometry>
    </collision>
  </link>
  <link name="ob7_slider_d_1">
    <inertial>
      <origin rpy="0 0 0" xyz="-0.04811466000799036 -0.668746099494158 -0.7750009636934996"/>
      <mass value="0.009612890331661439"/>
      <inertia ixx="3e-06" ixy="-0.0" ixz="-0.0" iyy="0.0" iyz="-0.0" izz="3e-06"/>
    </inertial>
    <visual>
      <origin rpy="0 0 0" xyz="-0.756306 -0.645957 -1.560159"/>
      <geometry>
        <mesh filename="package://mh5lsii_description/meshes/ob7_slider_d_1.stl" scale="0.001 0.001 0.001"/>
      </geometry>
      <material name="silver"/>
    </visual>
    <collision>
      <origin rpy="0 0 0" xyz="-0.756306 -0.645957 -1.560159"/>
      <geometry>
        <mesh filename="package://mh5lsii_description/meshes/ob7_slider_d_1.stl" scale="0.001 0.001 0.001"/>
      </geometry>
    </collision>
  </link>
  <link name="ob7_slider_i_1">
    <inertial>
      <origin rpy="0 0 0" xyz="0.053043310821363376 -0.6234089045465261 -0.7754502350968029"/>
      <mass value="0.009612890331661439"/>
      <inertia ixx="3e-06" ixy="0.0" ixz="0.0" iyy="0.0" iyz="-0.0" izz="3e-06"/>
    </inertial>
    <visual>
      <origin rpy="0 0 0" xyz="-0.655148 -0.646198 -1.530291"/>
      <geometry>
        <mesh filename="package://mh5lsii_description/meshes/ob7_slider_i_1.stl" scale="0.001 0.001 0.001"/>
      </geometry>
      <material name="silver"/>
    </visual>
    <collision>
      <origin rpy="0 0 0" xyz="-0.655148 -0.646198 -1.530291"/>
      <geometry>
        <mesh filename="package://mh5lsii_description/meshes/ob7_slider_i_1.stl" scale="0.001 0.001 0.001"/>
      </geometry>
    </collision>
  </link>
  <link name="ob7_finger_d_1">
    <inertial>
      <origin rpy="0 0 0" xyz="0.01307070022070067 -0.007894728170446508 -0.01047603512321127"/>
      <mass value="0.0070860389185776985"/>
      <inertia ixx="1e-06" ixy="0.0" ixz="0.0" iyy="2e-06" iyz="-0.0" izz="2e-06"/>
    </inertial>
    <visual>
      <origin rpy="0 0 0" xyz="-0.716674 0.045499 -0.784975"/>
      <geometry>
        <mesh filename="package://mh5lsii_description/meshes/ob7_finger_d_1.stl" scale="0.001 0.001 0.001"/>
      </geometry>
      <material name="silver"/>
    </visual>
    <collision>
      <origin rpy="0 0 0" xyz="-0.716674 0.045499 -0.784975"/>
      <geometry>
        <mesh filename="package://mh5lsii_description/meshes/ob7_finger_d_1.stl" scale="0.001 0.001 0.001"/>
      </geometry>
    </collision>
  </link>
  <link name="ob7_finger_i_1">
    <inertial>
      <origin rpy="0 0 0" xyz="0.013070691827939629 0.007894724006787111 0.010475794671614747"/>
      <mass value="0.0070860389185776985"/>
      <inertia ixx="1e-06" ixy="-0.0" ixz="-0.0" iyy="2e-06" iyz="-0.0" izz="2e-06"/>
    </inertial>
    <visual>
      <origin rpy="0 0 0" xyz="-0.716674 -0.045499 -0.755024"/>
      <geometry>
        <mesh filename="package://mh5lsii_description/meshes/ob7_finger_i_1.stl" scale="0.001 0.001 0.001"/>
      </geometry>
      <material name="silver"/>
    </visual>
    <collision>
      <origin rpy="0 0 0" xyz="-0.716674 -0.045499 -0.755024"/>
      <geometry>
        <mesh filename="package://mh5lsii_description/meshes/ob7_finger_i_1.stl" scale="0.001 0.001 0.001"/>
      </geometry>
    </collision>
  </link>
  <joint name="rev1" type="revolute">
    <origin rpy="0 0 0" xyz="0.0 0.0 0.229"/>
    <parent link="base_link"/>
    <child link="link_01_1"/>
    <axis xyz="0 -0.0 1.0"/>
    <limit effort="100" lower="-2.96706" upper="2.96706" velocity="100"/>
  </joint>
  <joint name="rev2" type="revolute">
    <origin rpy="0 0 0" xyz="0.088 -0.0635 0.101"/>
    <parent link="link_01_1"/>
    <child link="link_02_1"/>
    <axis xyz="-0.0 -1.0 -0.0"/>
    <limit effort="100" lower="-2.617994" upper="1.134464" velocity="100"/>
  </joint>
  <joint name="rev3" type="revolute">
    <origin rpy="0 0 0" xyz="0.0 0.128 0.4"/>
    <parent link="link_02_1"/>
    <child link="link_03_1"/>
    <axis xyz="-0.0 -1.0 0.0"/>
    <limit effort="100" lower="-0.558505" upper="3.316126" velocity="100"/>
  </joint>
  <joint name="rev4" type="continuous">
    <origin rpy="0 0 0" xyz="0.0705 -0.0645 0.04"/>
    <parent link="link_03_1"/>
    <child link="link_04_1"/>
    <axis xyz="1.0 -0.0 0"/>
  </joint>
  <joint name="rev5" type="revolute">
    <origin rpy="0 0 0" xyz="0.3345 0.030999 0.000249"/>
    <parent link="link_04_1"/>
    <child link="link_05_1"/>
    <axis xyz="-0.0 -1 -0"/>
    <limit effort="100" lower="-2.356194" upper="2.356194" velocity="100"/>
  </joint>
  <joint name="rev6" type="continuous">
    <origin rpy="0 0 0" xyz="0.0505 -0.030999 -0.000249"/>
    <parent link="link_05_1"/>
    <child link="link_06_1"/>
    <axis xyz="1.0 -0.0 -0"/>
  </joint>
  <joint name="rig7" type="fixed">
    <origin rpy="0 0 0" xyz="0.0235 0.0 0.0"/>
    <parent link="link_06_1"/>
    <child link="acople_1"/>
  </joint>
  <joint name="rig8" type="fixed">
    <origin rpy="0 0 0" xyz="0.023997 0.0 0.0"/>
    <parent link="acople_1"/>
    <child link="ob7_2_1"/>
  </joint>
  <joint name="slider9" type="prismatic">
    <origin rpy="0 0 0" xyz="0.165309 0.645957 0.790159"/>
    <parent link="ob7_2_1"/>
    <child link="ob7_slider_d_1"/>
    <axis xyz="-0.0 -1 -0"/>
    <limit effort="100" lower="-0.1" upper="-0.055" velocity="100"/>
  </joint>
  <joint name="slider10" type="prismatic">
    <origin rpy="0 0 0" xyz="0.064151 0.646198 0.760291"/>
    <parent link="ob7_2_1"/>
    <child link="ob7_slider_i_1"/>
    <axis xyz="0.0 1 0"/>
    <limit effort="100" lower="-0.1" upper="-0.055" velocity="100"/>
  </joint>
  <joint name="rig11" type="fixed">
    <origin rpy="0 0 0" xyz="-0.039632 -0.691456 -0.775184"/>
    <parent link="ob7_slider_d_1"/>
    <child link="ob7_finger_d_1"/>
  </joint>
  <joint name="rig12" type="fixed">
    <origin rpy="0 0 0" xyz="0.061526 -0.600699 -0.775267"/>
    <parent link="ob7_slider_i_1"/>
    <child link="ob7_finger_i_1"/>
  </joint>
</robot>

